<?xml version="1.0"?>

<robot name="bumper_bot">

  <!-- MATERIALS -->

  <material name="blue">
    <color rgba="0 0 1 1"/>
  </material>

  <material name="black">
    <color rgba="0 0 0 1"/>
  </material>

  <!-- BASE LINK -->

  <link name="base_link">

```
<visual>
  <origin xyz="0 0 0" rpy="0 0 0"/>
  <geometry>
    <box size="0.30 0.25 0.05"/>
  </geometry>
  <material name="blue"/>
</visual>

<collision>
  <origin xyz="0 0 0" rpy="0 0 0"/>
  <geometry>
    <box size="0.30 0.25 0.05"/>
  </geometry>
</collision>

<inertial>
  <mass value="1.0"/>
  <inertia ixx="0.01" ixy="0" ixz="0"
           iyy="0.01" iyz="0"
           izz="0.01"/>
</inertial>
```

  </link>

  <!-- LEFT WHEEL -->

  <link name="left_wheel">

```
<visual>
  <origin xyz="0 0 0" rpy="1.5708 0 0"/>
  <geometry>
    <cylinder radius="0.06" length="0.03"/>
  </geometry>
  <material name="black"/>
</visual>

<collision>
  <origin xyz="0 0 0" rpy="1.5708 0 0"/>
  <geometry>
    <cylinder radius="0.06" length="0.03"/>
  </geometry>
</collision>

<inertial>
  <mass value="0.2"/>
  <inertia ixx="0.001" ixy="0" ixz="0"
           iyy="0.001" iyz="0"
           izz="0.001"/>
</inertial>
```

  </link>

  <!-- RIGHT WHEEL -->

  <link name="right_wheel">

```
<visual>
  <origin xyz="0 0 0" rpy="1.5708 0 0"/>
  <geometry>
    <cylinder radius="0.06" length="0.03"/>
  </geometry>
  <material name="black"/>
</visual>

<collision>
  <origin xyz="0 0 0" rpy="1.5708 0 0"/>
  <geometry>
    <cylinder radius="0.06" length="0.03"/>
  </geometry>
</collision>

<inertial>
  <mass value="0.2"/>
  <inertia ixx="0.001" ixy="0" ixz="0"
           iyy="0.001" iyz="0"
           izz="0.001"/>
</inertial>
```

  </link>

  <!-- WHEEL JOINTS -->

  <joint name="left_wheel_joint" type="continuous">
    <parent link="base_link"/>
    <child link="left_wheel"/>
    <origin xyz="0 0.13 -0.06" rpy="0 0 0"/>
    <axis xyz="0 1 0"/>
  </joint>

  <joint name="right_wheel_joint" type="continuous">
    <parent link="base_link"/>
    <child link="right_wheel"/>
    <origin xyz="0 -0.13 -0.06" rpy="0 0 0"/>
    <axis xyz="0 1 0"/>
  </joint>

  <!-- LIDAR LINK -->

  <link name="lidar_link">

```
<visual>
  <origin xyz="0 0 0" rpy="0 0 0"/>
  <geometry>
    <cylinder radius="0.05" length="0.05"/>
  </geometry>
  <material name="black"/>
</visual>

<collision>
  <origin xyz="0 0 0" rpy="0 0 0"/>
  <geometry>
    <cylinder radius="0.05" length="0.05"/>
  </geometry>
</collision>

<inertial>
  <mass value="0.1"/>
  <inertia ixx="0.001" ixy="0" ixz="0"
           iyy="0.001" iyz="0"
           izz="0.001"/>
</inertial>
```

  </link>

  <!-- LIDAR JOINT -->

  <joint name="lidar_joint" type="fixed">
    <parent link="base_link"/>
    <child link="lidar_link"/>
    <origin xyz="0 0 0.15" rpy="0 0 0"/>
  </joint>

  <!-- DIFFERENTIAL DRIVE PLUGIN -->

  <gazebo>
    <plugin name="diff_drive" filename="libgazebo_ros_diff_drive.so">

```
  <ros>
    <namespace>/</namespace>
  </ros>

  <update_rate>50</update_rate>

  <left_joint>left_wheel_joint</left_joint>
  <right_joint>right_wheel_joint</right_joint>

  <wheel_separation>0.26</wheel_separation>
  <wheel_diameter>0.12</wheel_diameter>

  <command_topic>cmd_vel</command_topic>
  <odometry_topic>odom</odometry_topic>

  <odometry_frame>odom</odometry_frame>
  <robot_base_frame>base_link</robot_base_frame>

</plugin>
```

  </gazebo>

  <!-- LIDAR SENSOR -->

  <gazebo reference="lidar_link">

```
<sensor type="ray" name="lidar_sensor">

  <update_rate>10</update_rate>

  <ray>

    <scan>
      <horizontal>
        <samples>360</samples>
        <resolution>1</resolution>
        <min_angle>-3.14</min_angle>
        <max_angle>3.14</max_angle>
      </horizontal>
    </scan>

    <range>
      <min>0.12</min>
      <max>8.0</max>
      <resolution>0.01</resolution>
    </range>

  </ray>

  <plugin name="gazebo_ros_laser" filename="libgazebo_ros_ray_sensor.so">

    <ros>
      <remapping>~/out:=scan</remapping>
    </ros>

    <frame_name>lidar_link</frame_name>

    <output_type>sensor_msgs/LaserScan</output_type>

  </plugin>

</sensor>
```

  </gazebo>

</robot>

